Workbook

Sheet Sheet1
A1: reporter_name | B1: mean_total_rai | C1: impTop5Count | D1: expTop5Count | E1: impTop5 | F1: expTop5 | G1: Top 5 | H1: impTop10Count | I1: expTop10Count | J1: Imp Top 10 | K1: Exp Top 10 | L1: Top 10
A2: Albania | B2: 37.967416 | C2: 0 | D2: 0 | E2: 0 | F2: 0 | G2: =IF(OR(E2=1,F2=1),1,0) -> 0 | H2: =COUNTIFS(Sheet3!$R$2:$R$3528,1,Sheet3!$B$2:$B$3528,A2) -> 0 | I2: =COUNTIFS(Sheet3!$S$2:$S$3528,1,Sheet3!$B$2:$B$3528,A2) -> 0 | J2: =IF(H2>0,1,0) -> 0 | K2: =IF(I2>0,1,0) -> 0 | L2: =IF(OR(J2=1,K2=1),1,0) -> 0
A3: Algeria | B3: 57.431486 | C3: 0 | D3: 0 | E3: 0 | F3: 0 | G3: =IF(OR(E3=1,F3=1),1,0) -> 0 | H3: =COUNTIFS(Sheet3!$R$2:$R$3528,1,Sheet3!$B$2:$B$3528,A3) -> 1 | I3: =COUNTIFS(Sheet3!$S$2:$S$3528,1,Sheet3!$B$2:$B$3528,A3) -> 0 | J3: =IF(H3>0,1,0) -> 1 | K3: =IF(I3>0,1,0) -> 0 | L3: =IF(OR(J3=1,K3=1),1,0) -> 1
A4: Angola | B4: 39.663425 | C4: 1 | D4: 0 | E4: 1 | F4: 0 | G4: =IF(OR(E4=1,F4=1),1,0) -> 1 | H4: =COUNTIFS(Sheet3!$R$2:$R$3528,1,Sheet3!$B$2:$B$3528,A4) -> 1 | I4: =COUNTIFS(Sheet3!$S$2:$S$3528,1,Sheet3!$B$2:$B$3528,A4) -> 0 | J4: =IF(H4>0,1,0) -> 1 | K4: =IF(I4>0,1,0) -> 0 | L4: =IF(OR(J4=1,K4=1),1,0) -> 1
A5: Armenia | B5: 171.33839 | C5: 10 | D5: 1 | E5: 1 | F5: 1 | G5: =IF(OR(E5=1,F5=1),1,0) -> 1 | H5: =COUNTIFS(Sheet3!$R$2:$R$3528,1,Sheet3!$B$2:$B$3528,A5) -> 42 | I5: =COUNTIFS(Sheet3!$S$2:$S$3528,1,Sheet3!$B$2:$B$3528,A5) -> 3 | J5: =IF(H5>0,1,0) -> 1 | K5: =IF(I5>0,1,0) -> 1 | L5: =IF(OR(J5=1,K5=1),1,0) -> 1
A6: Azerbaijan | B6: 483.10993 | C6: 16 | D6: 2 | E6: 1 | F6: 1 | G6: =IF(OR(E6=1,F6=1),1,0) -> 1 | H6: =COUNTIFS(Sheet3!$R$2:$R$3528,1,Sheet3!$B$2:$B$3528,A6) -> 35 | I6: =COUNTIFS(Sheet3!$S$2:$S$3528,1,Sheet3!$B$2:$B$3528,A6) -> 3 | J6: =IF(H6>0,1,0) -> 1 | K6: =IF(I6>0,1,0) -> 1 | L6: =IF(OR(J6=1,K6=1),1,0) -> 1
A7: Belarus | B7: 238.23334 | C7: 70 | D7: 47 | E7: 1 | F7: 1 | G7: =IF(OR(E7=1,F7=1),1,0) -> 1 | H7: =COUNTIFS(Sheet3!$R$2:$R$3528,1,Sheet3!$B$2:$B$3528,A7) -> 79 | I7: =COUNTIFS(Sheet3!$S$2:$S$3528,1,Sheet3!$B$2:$B$3528,A7) -> 74 | J7: =IF(H7>0,1,0) -> 1 | K7: =IF(I7>0,1,0) -> 1 | L7: =IF(OR(J7=1,K7=1),1,0) -> 1
A8: Benin | B8: 41.643897 | C8: 0 | D8: 0 | E8: 0 | F8: 0 | G8: =IF(OR(E8=1,F8=1),1,0) -> 0 | H8: =COUNTIFS(Sheet3!$R$2:$R$3528,1,Sheet3!$B$2:$B$3528,A8) -> 0 | I8: =COUNTIFS(Sheet3!$S$2:$S$3528,1,Sheet3!$B$2:$B$3528,A8) -> 0 | J8: =IF(H8>0,1,0) -> 0 | K8: =IF(I8>0,1,0) -> 0 | L8: =IF(OR(J8=1,K8=1),1,0) -> 0
A9: Burkina Faso | B9: 100.63576 | C9: 1 | D9: 0 | E9: 1 | F9: 0 | G9: =IF(OR(E9=1,F9=1),1,0) -> 1 | H9: =COUNTIFS(Sheet3!$R$2:$R$3528,1,Sheet3!$B$2:$B$3528,A9) -> 1 | I9: =COUNTIFS(Sheet3!$S$2:$S$3528,1,Sheet3!$B$2:$B$3528,A9) -> 0 | J9: =IF(H9>0,1,0) -> 1 | K9: =IF(I9>0,1,0) -> 0 | L9: =IF(OR(J9=1,K9=1),1,0) -> 1
A10: Cambodia | B10: 30.857489 | C10: 0 | D10: 0 | E10: 0 | F10: 0 | G10: =IF(OR(E10=1,F10=1),1,0) -> 0 | H10: =COUNTIFS(Sheet3!$R$2:$R$3528,1,Sheet3!$B$2:$B$3528,A10) -> 0 | I10: =COUNTIFS(Sheet3!$S$2:$S$3528,1,Sheet3!$B$2:$B$3528,A10) -> 0 | J10: =IF(H10>0,1,0) -> 0 | K10: =IF(I10>0,1,0) -> 0 | L10: =IF(OR(J10=1,K10=1),1,0) -> 0
A11: Cameroon | B11: 62.358898 | C11: 0 | D11: 0 | E11: 0 | F11: 0 | G11: =IF(OR(E11=1,F11=1),1,0) -> 0 | H11: =COUNTIFS(Sheet3!$R$2:$R$3528,1,Sheet3!$B$2:$B$3528,A11) -> 0 | I11: =COUNTIFS(Sheet3!$S$2:$S$3528,1,Sheet3!$B$2:$B$3528,A11) -> 0 | J11: =IF(H11>0,1,0) -> 0 | K11: =IF(I11>0,1,0) -> 0 | L11: =IF(OR(J11=1,K11=1),1,0) -> 0
A12: Colombia | B12: 8.90115 | C12: 0 | D12: 0 | E12: 0 | F12: 0 | G12: =IF(OR(E12=1,F12=1),1,0) -> 0 | H12: =COUNTIFS(Sheet3!$R$2:$R$3528,1,Sheet3!$B$2:$B$3528,A12) -> 0 | I12: =COUNTIFS(Sheet3!$S$2:$S$3528,1,Sheet3!$B$2:$B$3528,A12) -> 2 | J12: =IF(H12>0,1,0) -> 0 | K12: =IF(I12>0,1,0) -> 1 | L12: =IF(OR(J12=1,K12=1),1,0) -> 1
A13: Ecuador | B13: 10.35238 | C13: 0 | D13: 2 | E13: 0 | F13: 1 | G13: =IF(OR(E13=1,F13=1),1,0) -> 1 | H13: =COUNTIFS(Sheet3!$R$2:$R$3528,1,Sheet3!$B$2:$B$3528,A13) -> 0 | I13: =COUNTIFS(Sheet3!$S$2:$S$3528,1,Sheet3!$B$2:$B$3528,A13) -> 3 | J13: =IF(H13>0,1,0) -> 0 | K13: =IF(I13>0,1,0) -> 1 | L13: =IF(OR(J13=1,K13=1),1,0) -> 1
... A53: Uzbekistan | B53: 224.8741 | C53: 20 | D53: 6 | E53: 1 | F53: 1 | G53: =IF(OR(E53=1,F53=1),1,0) -> 1 | H53: =COUNTIFS(Sheet3!$R$2:$R$3528,1,Sheet3!$B$2:$B$3528,A53) -> 42 | I53: =COUNTIFS(Sheet3!$S$2:$S$3528,1,Sheet3!$B$2:$B$3528,A53) -> 13 | J53: =IF(H53>0,1,0) -> 1 | K53: =IF(I53>0,1,0) -> 1 | L53: =IF(OR(J53=1,K53=1),1,0) -> 1

Sheet Sheet3
A1: reporter_iso | B1: reporter_name | C1: partner_iso | D1: partner_name | E1: section_code | F1: section_name | G1: HS2 | H1: imp_sum_hs2 | I1: exp_sum_hs2_5yr | J1: imp_rank_hs2_5yr | K1: exp_rank_hs2_5yr | L1: tbal_HS2_5yr | M1: import_factor | N1: export_factor | O1: trade_share | P1: impTop5 | Q1: expTop5 | R1: impTop10 | S1: expTop10 | T1: mean_total_rai | U1: Top 5 | V1: Top10
A2: alb | B2: Albania | C2: rus | D2: Russian Federation | E2: 99 | F2: NA | G2: 99 | H2: 276085188 | I2: 2876409 | J2: 17 | K2: 42 | L2: -273208779 | M2: 0.9896888710455727 | N2: 0.010311128954427371 | O2: 0.5181693002135614 | P2: 0 | Q2: 0 | R2: 0 | S2: 0 | T2: 37.967416 | U2: =IF(OR(P2=1,Q2=1),1,0) -> 0 | V2: =IF(OR(R2=1,S2=1),1,0) -> 0
A3: alb | B3: Albania | C3: rus | D3: Russian Federation | E3: 02 | F3: Vegetable products | G3: 10 | H3: 145961276 | I3: 0 | J3: 44 | K3: 65 | L3: -145961276 | M3: 1 | N3: 0 | O3: 0.2711220937095456 | P3: 0 | Q3: 0 | R3: 0 | S3: 0 | T3: 37.967416 | U3: =IF(OR(P3=1,Q3=1),1,0) -> 0 | V3: =IF(OR(R3=1,S3=1),1,0) -> 0
A4: alb | B4: Albania | C4: rus | D4: Russian Federation | E4: 05 | F4: Mineral products | G4: 27 | H4: 71064515 | I4: 0 | J4: 87 | K4: 91 | L4: -71064515 | M4: 1 | N4: 0 | O4: 0.1320018612008668 | P4: 0 | Q4: 0 | R4: 0 | S4: 0 | T4: 37.967416 | U4: =IF(OR(P4=1,Q4=1),1,0) -> 0 | V4: =IF(OR(R4=1,S4=1),1,0) -> 0
A5: alb | B5: Albania | C5: rus | D5: Russian Federation | E5: 15 | F5: Base metals and articles of base metal | G5: 76 | H5: 14067248 | I5: 0 | J5: 60 | K5: 92 | L5: -14067248 | M5: 1 | N5: 0 | O5: 0.026129819 | P5: 0 | Q5: 0 | R5: 0 | S5: 0 | T5: 37.967416 | U5: =IF(OR(P5=1,Q5=1),1,0) -> 0 | V5: =IF(OR(R5=1,S5=1),1,0) -> 0
A6: alb | B6: Albania | C6: rus | D6: Russian Federation | E6: 06 | F6: Product of the chemicals or allied industries | G6: 31 | H6: 19715122 | I6: 0 | J6: 90 | K6: 51 | L6: -19715122 | M6: 1 | N6: 0 | O6: 0.036620707 | P6: 0 | Q6: 0 | R6: 0 | S6: 0 | T6: 37.967416 | U6: =IF(OR(P6=1,Q6=1),1,0) -> 0 | V6: =IF(OR(R6=1,S6=1),1,0) -> 0
A7: alb | B7: Albania | C7: rus | D7: Russian Federation | E7: 13 | F7: Articles of stone, plaster, cement, asbestos, mica, or similar materials, ceramic products, glass and glassware | G7: 70 | H7: 1524622 | I7: 0 | J7: 55 | K7: 88 | L7: -1524622 | M7: 1 | N7: 0 | O7: 0.0028319752 | P7: 0 | Q7: 0 | R7: 0 | S7: 0 | T7: 37.967416 | U7: =IF(OR(P7=1,Q7=1),1,0) -> 0 | V7: =IF(OR(R7=1,S7=1),1,0) -> 0
A8: alb | B8: Albania | C8: rus | D8: Russian Federation | E8: 15 | F8: Base metals and articles of base metal | G8: 72 | H8: 267052 | I8: 0 | J8: 115 | K8: 74 | L8: -267052 | M8: 1 | N8: 0 | O8: 4.960473034595942e-4 | P8: 0 | Q8: 0 | R8: 0 | S8: 0 | T8: 37.967416 | U8: =IF(OR(P8=1,Q8=1),1,0) -> 0 | V8: =IF(OR(R8=1,S8=1),1,0) -> 0
A9: alb | B9: Albania | C9: rus | D9: Russian Federation | E9: 09 | F9: Wood and articles of wood, wood charcoal, cork and articles of cork, manufacturers of straw, of esparto or of other plaiting materials, basketwork and wickerwork | G9: 44 | H9: 751395 | I9: 0 | J9: 97 | K9: 103 | L9: -751395 | M9: 1 | N9: 0 | O9: 0.0013957112 | P9: 0 | Q9: 0 | R9: 0 | S9: 0 | T9: 37.967416 | U9: =IF(OR(P9=1,Q9=1),1,0) -> 0 | V9: =IF(OR(R9=1,S9=1),1,0) -> 0
A10: alb | B10: Albania | C10: rus | D10: Russian Federation | E10: 16 | F10: Machinery and mechanical appliances, electrical equipment, parts thereof, sound recorders and reproducers, television image and souch recorders and reproducers, and parts and accessories of such articles | G10: 84 | H10: 203073 | I10: 0 | J10: 129 | K10: 117 | L10: -203073 | M10: 1 | N10: 0 | O10: 3.7720673897012624e-4 | P10: 0 | Q10: 0 | R10: 0 | S10: 0 | T10: 37.967416 | U10: =IF(OR(P10=1,Q10=1),1,0) -> 0 | V10: =IF(OR(R10=1,S10=1),1,0) -> 0
A11: alb | B11: Albania | C11: rus | D11: Russian Federation | E11: 17 | F11: Vehicles, aircraft, vessels and associated transport equipment | G11: 87 | H11: 157731 | I11: 0 | J11: 116 | K11: 96 | L11: -157731 | M11: 1 | N11: 0 | O11: 2.929842773017436e-4 | P11: 0 | Q11: 0 | R11: 0 | S11: 0 | T11: 37.967416 | U11: =IF(OR(P11=1,Q11=1),1,0) -> 0 | V11: =IF(OR(R11=1,S11=1),1,0) -> 0
A12: alb | B12: Albania | C12: rus | D12: Russian Federation | E12: 07 | F12: Plastics and articles thereof, rubber and articles thereof | G12: 40 | H12: 353856 | I12: 0 | J12: 96 | K12: 97 | L12: -353856 | M12: 1 | N12: 0 | O12: 6.572851527530148e-4 | P12: 0 | Q12: 0 | R12: 0 | S12: 0 | T12: 37.967416 | U12: =IF(OR(P12=1,Q12=1),1,0) -> 0 | V12: =IF(OR(R12=1,S12=1),1,0) -> 0
A13: alb | B13: Albania | C13: rus | D13: Russian Federation | E13: 07 | F13: Plastics and articles thereof, rubber and articles thereof | G13: 39 | H13: 83631 | I13: 0 | J13: 113 | K13: 109 | L13: -83631 | M13: 1 | N13: 0 | O13: 1.5534402302034553e-4 | P13: 0 | Q13: 0 | R13: 0 | S13: 0 | T13: 37.967416 | U13: =IF(OR(P13=1,Q13=1),1,0) -> 0 | V13: =IF(OR(R13=1,S13=1),1,0) -> 0
A14: alb | B14: Albania | C14: rus | D14: Russian Federation | E14: 02 | F14: Vegetable products | G14: 12 | H14: 8430 | I14: 0 | J14: 83 | K14: 98 | L14: -8430 | M14: 1 | N14: 0 | O14: 1.565866860448294e-5 | P14: 0 | Q14: 0 | R14: 0 | S14: 0 | T14: 37.967416 | U14: =IF(OR(P14=1,Q14=1),1,0) -> 0 | V14: =IF(OR(R14=1,S14=1),1,0) -> 0
A15: alb | B15: Albania | C15: rus | D15: Russian Federation | E15: 20 | F15: Miscellaneous manufactured articles | G15: 95 | H15: 0 | I15: 116041 | J15: 130 | K15: 64 | L15: 116041 | M15: 0 | N15: 1 | O15: 2.1554538120199346e-4 | P15: 0 | Q15: 0 | R15: 0 | S15: 0 | T15: 37.967416 | U15: =IF(OR(P15=1,Q15=1),1,0) -> 0 | V15: =IF(OR(R15=1,S15=1),1,0) -> 0
A16: dza | B16: Algeria | C16: rus | D16: Russian Federation | E16: 05 | F16: Mineral products | G16: 27 | H16: 272218459 | I16: 34225 | J16: 73 | K16: 79 | L16: -272184234 | M16: 0.9998742895772517 | N16: 1.2571042274830244e-4 | O16: 0.13600642635793805 | P16: 0 | Q16: 0 | R16: 0 | S16: 0 | T16: 57.431486 | U16: =IF(OR(P16=1,Q16=1),1,0) -> 0 | V16: =IF(OR(R16=1,S16=1),1,0) -> 0
A17: dza | B17: Algeria | C17: rus | D17: Russian Federation | E17: 03 | F17: Animal or vegetable fats and oils and their cleavage products; prepared edible fats; animal or vegetble waxes | G17: 15 | H17: 373311108 | I17: 2728 | J17: 9 | K17: 78 | L17: -373308380 | M17: 0.9999926924755074 | N17: 7.307524492609484e-6 | O17: 0.1864924892506601 | P17: 0 | Q17: 0 | R17: 1 | S17: 0 | T17: 57.431486 | U17: =IF(OR(P17=1,Q17=1),1,0) -> 0 | V17: =IF(OR(R17=1,S17=1),1,0) -> 1
A18: dza | B18: Algeria | C18: rus | D18: Russian Federation | E18: 17 | F18: Vehicles, aircraft, vessels and associated transport equipment | G18: 88 | H18: 116976625 | I18: 1370831 | J18: 12 | K18: 44 | L18: -115605794 | M18: 0.9884168950788431 | N18: 0.011583104921156903 | O18: 0.059121601 | P18: 0 | Q18: 0 | R18: 0 | S18: 0 | T18: 57.431486 | U18: =IF(OR(P18=1,Q18=1),1,0) -> 0 | V18: =IF(OR(R18=1,S18=1),1,0) -> 0
A19: dza | B19: Algeria | C19: rus | D19: Russian Federation | E19: 15 | F19: Base metals and articles of base metal | G19: 72 | H19: 593766506 | I19: 0 | J19: 29 | K19: 74 | L19: -593766506 | M19: 1 | N19: 0 | O19: 0.2966217242952844 | P19: 0 | Q19: 0 | R19: 0 | S19: 0 | T19: 57.431486 | U19: =IF(OR(P19=1,Q19=1),1,0) -> 0 | V19: =IF(OR(R19=1,S19=1),1,0) -> 0
A20: dza | B20: Algeria | C20: rus | D20: Russian Federation | E20: 02 | F20: Vegetable products | G20: 10 | H20: 64943498 | I20: 0 | J20: 63 | K20: 65 | L20: -64943498 | M20: 1 | N20: 0 | O20: 0.032443144 | P20: 0 | Q20: 0 | R20: 0 | S20: 0 | T20: 57.431486 | U20: =IF(OR(P20=1,Q20=1),1,0) -> 0 | V20: =IF(OR(R20=1,S20=1),1,0) -> 0
A21: dza | B21: Algeria | C21: rus | D21: Russian Federation | E21: 02 | F21: Vegetable products | G21: 07 | H21: 13684757 | I21: 449 | J21: 25 | K21: 82 | L21: -13684308 | M21: 0.99996719 | N21: 3.280915172193974e-5 | O21: 0.0068365753 | P21: 0 | Q21: 0 | R21: 0 | S21: 0 | T21: 57.431486 | U21: =IF(OR(P21=1,Q21=1),1,0) -> 0 | V21: =IF(OR(R21=1,S21=1),1,0) -> 0
A22: dza | B22: Algeria | C22: rus | D22: Russian Federation | E22: 15 | F22: Base metals and articles of base metal | G22: 82 | H22: 11253145 | I22: 0 | J22: 17 | K22: 96 | L22: -11253145 | M22: 1 | N22: 0 | O22: 0.005621616 | P22: 0 | Q22: 0 | R22: 0 | S22: 0 | T22: 57.431486 | U22: =IF(OR(P22=1,Q22=1),1,0) -> 0 | V22: =IF(OR(R22=1,S22=1),1,0) -> 0
A23: dza | B23: Algeria | C23: rus | D23: Russian Federation | E23: 15 | F23: Base metals and articles of base metal | G23: 73 | H23: 17174226 | I23: 0 | J23: 42 | K23: 103 | L23: -17174226 | M23: 1 | N23: 0 | O23: 0.0085795485 | P23: 0 | Q23: 0 | R23: 0 | S23: 0 | T23: 57.431486 | U23: =IF(OR(P23=1,Q23=1),1,0) -> 0 | V23: =IF(OR(R23=1,S23=1),1,0) -> 0
A24: dza | B24: Algeria | C24: rus | D24: Russian Federation | E24: 10 | F24: Pulp of wood or of other fibrous cellulosic material, recovered (waste and scrap) paper or paperboard, paper and paperboard and articles thereof | G24: 48 | H24: 8716893 | I24: 1141 | J24: 77 | K24: 83 | L24: -8715752 | M24: 0.9998691218685314 | N24: 1.3087813146863157e-4 | O24: 0.0043551771 | P24: 0 | Q24: 0 | R24: 0 | S24: 0 | T24: 57.431486 | U24: =IF(OR(P24=1,Q24=1),1,0) -> 0 | V24: =IF(OR(R24=1,S24=1),1,0) -> 0
A25: dza | B25: Algeria | C25: rus | D25: Russian Federation | E25: 07 | F25: Plastics and articles thereof, rubber and articles thereof | G25: 40 | H25: 3350479 | I25: 0 | J25: 68 | K25: 97 | L25: -3350479 | M25: 1 | N25: 0 | O25: 0.0016737638 | P25: 0 | Q25: 0 | R25: 0 | S25: 0 | T25: 57.431486 | U25: =IF(OR(P25=1,Q25=1),1,0) -> 0 | V25: =IF(OR(R25=1,S25=1),1,0) -> 0
A26: dza | B26: Algeria | C26: rus | D26: Russian Federation | E26: 06 | F26: Product of the chemicals or allied industries | G26: 31 | H26: 7835639 | I26: 0 | J26: 103 | K26: 51 | L26: -7835639 | M26: 1 | N26: 0 | O26: 0.0039143682 | P26: 0 | Q26: 0 | R26: 0 | S26: 0 | T26: 57.431486 | U26: =IF(OR(P26=1,Q26=1),1,0) -> 0 | V26: =IF(OR(R26=1,S26=1),1,0) -> 0
A27: dza | B27: Algeria | C27: rus | D27: Russian Federation | E27: 06 | F27: Product of the chemicals or allied industries | G27: 28 | H27: 9835649 | I27: 0 | J27: 76 | K27: 85 | L27: -9835649 | M27: 1 | N27: 0 | O27: 0.0049134923 | P27: 0 | Q27: 0 | R27: 0 | S27: 0 | T27: 57.431486 | U27: =IF(OR(P27=1,Q27=1),1,0) -> 0 | V27: =IF(OR(R27=1,S27=1),1,0) -> 0
A28: dza | B28: Algeria | C28: rus | D28: Russian Federation | E28: 07 | F28: Plastics and articles thereof, rubber and articles thereof | G28: 39 | H28: 3235808 | I28: 0 | J28: 69 | K28: 109 | L28: -3235808 | M28: 1 | N28: 0 | O28: 0.0016164788 | P28: 0 | Q28: 0 | R28: 0 | S28: 0 | T28: 57.431486 | U28: =IF(OR(P28=1,Q28=1),1,0) -> 0 | V28: =IF(OR(R28=1,S28=1),1,0) -> 0
A29: dza | B29: Algeria | C29: rus | D29: Russian Federation | E29: 16 | F29: Machinery and mechanical appliances, electrical equipment, parts thereof, sound recorders and reproducers, television image and souch recorders and reproducers, and parts and accessories of such articles | G29: 84 | H29: 20495514 | I29: 10626 | J29: 56 | K29: 102 | L29: -20484888 | M29: 0.9994818137396897 | N29: 5.181862603103266e-4 | O29: 0.010244037923958787 | P29: 0 | Q29: 0 | R29: 0 | S29: 0 | T29: 57.431486 | U29: =IF(OR(P29=1,Q29=1),1,0) -> 0 | V29: =IF(OR(R29=1,S29=1),1,0) -> 0
A30: dza | B30: Algeria | C30: rus | D30: Russian Federation | E30: 06 | F30: Product of the chemicals or allied industries | G30: 38 | H30: 5566416 | I30: 0 | J30: 50 | K30: 87 | L30: -5566416 | M30: 1 | N30: 0 | O30: 0.0027807562 | P30: 0 | Q30: 0 | R30: 0 | S30: 0 | T30: 57.431486 | U30: =IF(OR(P30=1,Q30=1),1,0) -> 0 | V30: =IF(OR(R30=1,S30=1),1,0) -> 0
A31: dza | B31: Algeria | C31: rus | D31: Russian Federation | E31: 16 | F31: Machinery and mechanical appliances, electrical equipment, parts thereof, sound recorders and reproducers, television image and souch recorders and reproducers, and parts and accessories of such articles | G31: 85 | H31: 177185588 | I31: 1160595 | J31: 19 | K31: 69 | L31: -176024993 | M31: 0.9934924595498632 | N31: 0.0065075405 | O31: 0.089094538 | P31: 0 | Q31: 0 | R31: 0 | S31: 0 | T31: 57.431486 | U31: =IF(OR(P31=1,Q31=1),1,0) -> 0 | V31: =IF(OR(R31=1,S31=1),1,0) -> 0
A32: dza | B32: Algeria | C32: rus | D32: Russian Federation | E32: 15 | F32: Base metals and articles of base metal | G32: 74 | H32: 975164 | I32: 0 | J32: 65 | K32: 84 | L32: -975164 | M32: 1 | N32: 0 | O32: 4.871524820409568e-4 | P32: 0 | Q32: 0 | R32: 0 | S32: 0 | T32: 57.431486 | U32: =IF(OR(P32=1,Q32=1),1,0) -> 0 | V32: =IF(OR(R32=1,S32=1),1,0) -> 0
A33: dza | B33: Algeria | C33: rus | D33: Russian Federation | E33: 11 | F33: Textile and textile articles | G33: 56 | H33: 2184567 | I33: 0 | J33: 33 | K33: 77 | L33: -2184567 | M33: 1 | N33: 0 | O33: 0.0010913213 | P33: 0 | Q33: 0 | R33: 0 | S33: 0 | T33: 57.431486 | U33: =IF(OR(P33=1,Q33=1),1,0) -> 0 | V33: =IF(OR(R33=1,S33=1),1,0) -> 0
A34: dza | B34: Algeria | C34: rus | D34: Russian Federation | E34: 05 | F34: Mineral products | G34: 25 | H34: 1386758 | I34: 78 | J34: 69 | K34: 89 | L34: -1386680 | M34: 0.9999437568681516 | N34: 5.624313184832237e-5 | O34: 6.928071581639113e-4 | P34: 0 | Q34: 0 | R34: 0 | S34: 0 | T34: 57.431486 | U34: =IF(OR(P34=1,Q34=1),1,0) -> 0 | V34: =IF(OR(R34=1,S34=1),1,0) -> 0
A35: dza | B35: Algeria | C35: rus | D35: Russian Federation | E35: 17 | F35: Vehicles, aircraft, vessels and associated transport equipment | G35: 87 | H35: 92181856 | I35: 0 | J35: 16 | K35: 96 | L35: -92181856 | M35: 1 | N35: 0 | O35: 0.046050326 | P35: 0 | Q35: 0 | R35: 0 | S35: 0 | T35: 57.431486 | U35: =IF(OR(P35=1,Q35=1),1,0) -> 0 | V35: =IF(OR(R35=1,S35=1),1,0) -> 0
A36: dza | B36: Algeria | C36: rus | D36: Russian Federation | E36: 06 | F36: Product of the chemicals or allied industries | G36: 29 | H36: 1237632 | I36: 0 | J36: 89 | K36: 81 | L36: -1237632 | M36: 1 | N36: 0 | O36: 6.182708761329514e-4 | P36: 0 | Q36: 0 | R36: 0 | S36: 0 | T36: 57.431486 | U36: =IF(OR(P36=1,Q36=1),1,0) -> 0 | V36: =IF(OR(R36=1,S36=1),1,0) -> 0
A37: dza | B37: Algeria | C37: rus | D37: Russian Federation | E37: 06 | F37: Product of the chemicals or allied industries | G37: 33 | H37: 2167750 | I37: 0 | J37: 53 | K37: 95 | L37: -2167750 | M37: 1 | N37: 0 | O37: 0.0010829202 | P37: 0 | Q37: 0 | R37: 0 | S37: 0 | T37: 57.431486 | U37: =IF(OR(P37=1,Q37=1),1,0) -> 0 | V37: =IF(OR(R37=1,S37=1),1,0) -> 0
A38: dza | B38: Algeria | C38: rus | D38: Russian Federation | E38: 15 | F38: Base metals and articles of base metal | G38: 78 | H38: 188348 | I38: 0 | J38: 48 | K38: 44 | L38: -188348 | M38: 1 | N38: 0 | O38: 9.409104077616702e-5 | P38: 0 | Q38: 0 | R38: 0 | S38: 0 | T38: 57.431486 | U38: =IF(OR(P38=1,Q38=1),1,0) -> 0 | V38: =IF(OR(R38=1,S38=1),1,0) -> 0
A39: dza | B39: Algeria | C39: rus | D39: Russian Federation | E39: 09 | F39: Wood and articles of wood, wood charcoal, cork and articles of cork, manufacturers of straw, of esparto or of other plaiting materials, basketwork and wickerwork | G39: 44 | H39: 418087 | I39: 0 | J39: 104 | K39: 103 | L39: -418087 | M39: 1 | N39: 0 | O39: 2.0885935059031867e-4 | P39: 0 | Q39: 0 | R39: 0 | S39: 0 | T39: 57.431486 | U39: =IF(OR(P39=1,Q39=1),1,0) -> 0 | V39: =IF(OR(R39=1,S39=1),1,0) -> 0
A40: dza | B40: Algeria | C40: rus | D40: Russian Federation | E40: 02 | F40: Vegetable products | G40: 11 | H40: 444444 | I40: 0 | J40: 56 | K40: 71 | L40: -444444 | M40: 1 | N40: 0 | O40: 2.2202624146113988e-4 | P40: 0 | Q40: 0 | R40: 0 | S40: 0 | T40: 57.431486 | U40: =IF(OR(P40=1,Q40=1),1,0) -> 0 | V40: =IF(OR(R40=1,S40=1),1,0) -> 0
...

Sheet Sheet2
C3: Top 5 (Import or Export) | D3: Top 5 (Import) | E3: Top 5 (Export) | F3: Top 10 (Import or Export) | G3: Top 10 (Import) | H3: Top 10 (Export) | I3: Sample
B4: Mean Influence (RAI) | C4: =AVERAGEIFS(Sheet1!$B$2:$B$53,Sheet1!$G$2:$G$53,1) -> 151.44856 | D4: =AVERAGEIFS(Sheet1!$B$2:$B$53,Sheet1!$E$2:$E$53,1) -> 205.13657 | E4: =AVERAGEIFS(Sheet1!$B$2:$B$53,Sheet1!$F$2:$F$53,1) -> 184.21673 | F4: =AVERAGEIFS(Sheet1!$B$2:$B$53,Sheet1!$L$2:$L$53,1) -> 128.04422 | G4: =AVERAGEIFS(Sheet1!$B$2:$B$53,Sheet1!$J$2:$J$53,1) -> 171.17118 | H4: =AVERAGEIFS(Sheet1!$B$2:$B$53,Sheet1!$K$2:$K$53,1) -> 147.30262 | I4: =AVERAGE(Sheet1!$B$2:$B$53) -> 100.76516
B5: Multiple of Average | C5: =C4/$I4 -> 1.5029854 | D5: =D4/$I4 -> 2.0357887 | E5: =E4/$I4 -> 1.8281788 | F5: =F4/$I4 -> 1.2707193 | G5: =G4/$I4 -> 1.698714 | H5: =H4/$I4 -> 1.4618408
B6: Median Influence (RAI) | C6: {=IFERROR(MEDIAN(IF(Sheet1!$G$2:$G$53=1,Sheet1!$B$2:$B$53)),0)} -> 45.410769 | D6: {=IFERROR(MEDIAN(IF(Sheet1!$E$2:$E$53=1,Sheet1!$B$2:$B$53)),0)} -> 100.53711 | E6: {=IFERROR(MEDIAN(IF(Sheet1!$F$2:$F$53=1,Sheet1!$B$2:$B$53)),0)} -> 100.43847 | F6: {=IFERROR(MEDIAN(IF(Sheet1!$L$2:$L$53=1,Sheet1!$B$2:$B$53)),0)} -> 29.702585 | G6: {=IFERROR(MEDIAN(IF(Sheet1!$J$2:$J$53=1,Sheet1!$B$2:$B$53)),0)} -> 93.786791 | H6: {=IFERROR(MEDIAN(IF(Sheet1!$K$2:$K$53=1,Sheet1!$B$2:$B$53)),0)} -> 29.702585 | I6: =MEDIAN(Sheet1!B2:B53) -> 38.81542
B7: Multiple of Median | C7: =C6/$I6 -> 1.1699157 | D7: =D6/$I6 -> 2.5901333 | E7: =E6/$I6 -> 2.5875919 | F7: =F6/$I6 -> 0.76522642 | G7: =G6/$I6 -> 2.4162251 | H7: =H6/$I6 -> 0.76522642
B8: Count | C8: =COUNTIFS(Sheet1!$G$2:$G$53,1) -> 27 | D8: =COUNTIFS(Sheet1!$E$2:$E$53,1) -> 18 | E8: =COUNTIFS(Sheet1!$F$2:$F$53,1) -> 21 | F8: =COUNTIFS(Sheet1!$L$2:$L$53,1) -> 33 | G8: =COUNTIFS(Sheet1!$J$2:$J$53,1) -> 24 | H8: =COUNTIFS(Sheet1!$K$2:$K$53,1) -> 27 | I8: =COUNT(Sheet1!$B$2:$B$53) -> 52
C9: Not Top 5 (Import or Export) | D9: Not Top 5 (Import) | E9: Not Top 5 (Export) | F9: Not Top 10 (Import or Export) | G9: Not Top 10 (Import) | H9: Not Top 10 (Export) | I9: Sample
B10: Mean Influence (RAI) | C10: =AVERAGEIFS(Sheet1!$B$2:$B$53,Sheet1!$G$2:$G$53,0) -> 46.027084 | D10: =AVERAGEIFS(Sheet1!$B$2:$B$53,Sheet1!$E$2:$E$53,0) -> 45.509703 | E10: =AVERAGEIFS(Sheet1!$B$2:$B$53,Sheet1!$F$2:$F$53,0) -> 44.233447 | F10: =AVERAGEIFS(Sheet1!$B$2:$B$53,Sheet1!$L$2:$L$53,0) -> 53.385723 | G10: =AVERAGEIFS(Sheet1!$B$2:$B$53,Sheet1!$J$2:$J$53,0) -> 40.417137 | H10: =AVERAGEIFS(Sheet1!$B$2:$B$53,Sheet1!$K$2:$K$53,0) -> 50.504696 | I10: =AVERAGE(Sheet1!$B$2:$B$53) -> 100.76516
B11: Multiple of Average | C11: =C10/$I10 -> 0.45677579 | D11: =D10/$I10 -> 0.45164127 | E11: =E10/$I10 -> 0.43897562 | F11: =F10/$I10 -> 0.52980341 | G11: =G10/$I10 -> 0.40110231 | H11: =H10/$I10 -> 0.50121191
B12: Median Influence (RAI) | C12: {=IFERROR(MEDIAN(IF(Sheet1!$G$2:$G$53=0,Sheet1!$B$2:$B$53)),0)} -> 36.805438 | D12: {=IFERROR(MEDIAN(IF(Sheet1!$E$2:$E$53=0,Sheet1!$B$2:$B$53)),0)} -> 28.401802 | E12: {=IFERROR(MEDIAN(IF(Sheet1!$F$2:$F$53=0,Sheet1!$B$2:$B$53)),0)} -> 30.857489 | F12: {=IFERROR(MEDIAN(IF(Sheet1!$L$2:$L$53=0,Sheet1!$B$2:$B$53)),0)} -> 41.643897 | G12: {=IFERROR(MEDIAN(IF(Sheet1!$J$2:$J$53=0,Sheet1!$B$2:$B$53)),0)} -> 25.589071 | H12: {=IFERROR(MEDIAN(IF(Sheet1!$K$2:$K$53=0,Sheet1!$B$2:$B$53)),0)} -> 39.663425 | I12: =MEDIAN(Sheet1!B2:B53) -> 38.81542
B13: Multiple of Median | C13: =C12/$I12 -> 0.94821692 | D13: =D12/$I12 -> 0.73171439 | E13: =E12/$I12 -> 0.79498017 | F13: =F12/$I12 -> 1.0728699 | G13: =G12/$I12 -> 0.65925014 | H13: =H12/$I12 -> 1.0218471
B14: Count | C14: =COUNTIFS(Sheet1!$G$2:$G$53,0) -> 25 | D14: =COUNTIFS(Sheet1!$E$2:$E$53,0) -> 34 | E14: =COUNTIFS(Sheet1!$F$2:$F$53,0) -> 31 | F14: =COUNTIFS(Sheet1!$L$2:$L$53,0) -> 19 | G14: =COUNTIFS(Sheet1!$J$2:$J$53,0) -> 28 | H14: =COUNTIFS(Sheet1!$K$2:$K$53,0) -> 25 | I14: =COUNT(Sheet1!$B$2:$B$53) -> 52
C15: Top 5 Premium to Not Top 5
B16: Mean Influence (RAI) | C16: =C4/C10 -> 3.2904226 | D16: =D4/D10 -> 4.5075347 | E16: =E4/E10 -> 4.1646478 | F16: =F4/F10 -> 2.3984732 | G16: =G4/G10 -> 4.2351139 | H16: =H4/H10 -> 2.9166123
B17: Median Influence (RAI) | C17: =C6/C12 -> 1.233806 | D17: =D6/D12 -> 3.5398146 | E17: =E6/E12 -> 3.2549138 | F17: =F6/F12 -> 0.71325181 | G17: =G6/G12 -> 3.6651111 | H17: =H6/H12 -> 0.74886587
